Workbook
Name AsOfDate: 'Start Here'!$D$9

Sheet Start Here
B2: EA Operations Toolkit
B3: Prepared by Alliah (Ali) Puchero · Executive Assistant · Version 1.0 · October 2026
B5: A working set of the systems I use to support executives and small teams: standard operating procedures, trackers, research, workflow maps and reporting. Every tracker feeds the Dashboard and the Weekly Report automatically, so the numbers stay in sync as the work changes.
B7: Settings
B9: As-of date | D9: 46325 | E9: Every tracker measures “overdue”, “days left” and follow-up dates from this date. For live use, replace it with =TODAY().
B11: How to read this workbook
B12: Type here | E12: White cells are inputs: type, paste or choose from the drop-down list.
B13: Calculated | E13: Grey cells contain formulas and update automatically. Please don’t type over them.
B14: Header | E14: Burgundy rows are column headers. Most tables have filters, frozen headers and drop-downs.
B16: Contents
B17: # | C17: Tab | D17: Type | E17: What it’s for
B18: 1 | C18: Dashboard | D18: Report | E18: A live dashboard: 16 KPIs across tasks, receivables, pipeline, meetings, events and onboarding, plus a “needs attention” list.
B19: 2 | C19: Weekly Report | D19: Report | E19: A one-page weekly status report for the executive. Metrics pull live from the Dashboard; highlights and decisions are written each Friday.
B20: 3 | C20: SOP Library | D20: SOP | E20: A register of every SOP with owner, version and an automatic review schedule.
B21: 4 | C21: SOP-01 Inbox | D21: SOP | E21: How I triage an executive’s inbox twice a day: folders, flags, response times and the hand-off summary.
B22: 5 | C22: SOP-02 Meetings | D22: SOP | E22: Scheduling, confirmations, agendas, notes and action items, from invite to follow-up.
B23: 6 | C23: SOP-03 Onboarding | D23: SOP | E23: An eight-step onboarding checklist from signed engagement to kick-off call, tracked per client.
B24: 7 | C24: SOP-04 AR Follow-up | D24: SOP | E24: The weekly invoice follow-up routine in Xero: aging review, staged reminders, call script and record-keeping.
B25: 8 | C25: SOP-05 Webinars & CPD | D25: SOP | E25: Running a CPD webinar end to end: registrations, reminders, attendance and camera compliance, certificates.
B26: 9 | C26: Task Tracker | D26: Tracker | E26: Every request with owner, priority, due date and an automatic health flag (On track / Due soon / Overdue / Done).
B27: 10 | C27: AR Tracker | D27: Tracker | E27: Invoices with automatic due dates, aging buckets, follow-up stage (Reminder 1 → escalation) and next action date, plus an aging summary.
B28: 11 | C28: CRM Pipeline | D28: Tracker | E28: Leads by stage with probability looked up from the stage table, weighted value, days since contact and a follow-up flag.
B29: 12 | C29: Meeting Actions | D29: Tracker | E29: Decisions and action items from each meeting, with owner, due date and an automatic overdue flag.
... B36: 19 | C36: RACI Matrix | D36: Workflow | E36: Roles and responsibilities for 12 recurring activities, with a built-in check that every row has exactly one accountable owner.
B38: All clients, people, invoices, leads and figures in this workbook are fictitious placeholders created to demonstrate these systems. Any resemblance to real organisations is coincidental.

Sheet Dashboard
B1: Operations Dashboard
B2: ="Live summary of every tracker · as of "&DAY(AsOfDate)&"/"&MONTH(AsOfDate)&"/"&YEAR(AsOfDate) -> Live summary of every tracker · as of 30/10/2026
B4: Tasks
B5: Open tasks | D5: Overdue | F5: Due within 3 days | H5: Completion rate
B6: =COUNTA('Task Tracker'!$J$5:$J$22)-COUNTIF('Task Tracker'!$J$5:$J$22,"Completed") -> 14 | D6: =COUNTIF('Task Tracker'!$M$5:$M$22,"Overdue") -> 3 | F6: =COUNTIF('Task Tracker'!$M$5:$M$22,"Due soon") -> 5 | H6: =IFERROR(COUNTIF('Task Tracker'!$J$5:$J$22,"Completed")/COUNTA('Task Tracker'!$J$5:$J$22),0) -> 0.22222222
B8: Accounts receivable
B9: Total outstanding | D9: Overdue amount | F9: % of balance overdue | H9: Follow-ups due now
B10: =SUM('AR Tracker'!$J$5:$J$20) -> 43830 | D10: =SUMIFS('AR Tracker'!$J$5:$J$20,'AR Tracker'!$K$5:$K$20,">0") -> 23820 | F10: =IFERROR(D10/B10,0) -> 0.54346338 | H10: =COUNTIFS('AR Tracker'!$O$5:$O$20,"<="&AsOfDate,'AR Tracker'!$J$5:$J$20,">0") -> 6
B12: Pipeline
B13: Open leads | D13: Weighted pipeline | F13: Won (monthly value) | H13: Follow-ups due / overdue
B14: =COUNTA('CRM Pipeline'!$G$5:$G$18)-COUNTIF('CRM Pipeline'!$G$5:$G$18,"Won")-COUNTIF('CRM Pipeline'!$G$5:$G$18,"Lost") -> 11 | D14: =SUMIFS('CRM Pipeline'!$J$5:$J$18,'CRM Pipeline'!$G$5:$G$18,"<>Won",'CRM Pipeline'!$G$5:$G$18,"<>Lost") -> 12330 | F14: =SUMIFS('CRM Pipeline'!$H$5:$H$18,'CRM Pipeline'!$G$5:$G$18,"Won") -> 8400 | H14: =COUNTIF('CRM Pipeline'!$O$5:$O$18,"Overdue")+COUNTIF('CRM Pipeline'!$O$5:$O$18,"Due today") -> 5
B16: Meetings, events & onboarding
B17: Open meeting actions | D17: Overdue actions | F17: Webinar attendance rate | H17: Avg onboarding completion
B18: =COUNTIF('Meeting Actions'!$K$5:$K$18,"<>Closed") -> 10 | D18: =COUNTIF('Meeting Actions'!$K$5:$K$18,"Overdue") -> 3 | F18: ='Event & CPD Tracker'!$H$6 -> 0.875 | H18: =AVERAGE('Onboarding Tracker'!$M$5:$M$10) -> 0.54166667
B20: Needs attention
B21: Item | D21: Count | E21: Where
B22: Overdue tasks | D22: =COUNTIF('Task Tracker'!$M$5:$M$22,"Overdue") -> 3 | E22: Go to Task Tracker ›
B23: Invoices to escalate (45+ days) | D23: =COUNTIF('AR Tracker'!$N$5:$N$20,"Escalate to manager") -> 2 | E23: Go to AR Tracker ›
B24: Leads with overdue follow-up | D24: =COUNTIF('CRM Pipeline'!$O$5:$O$18,"Overdue") -> 4 | E24: Go to CRM Pipeline ›
B25: CPD certificates to send | D25: ='Event & CPD Tracker'!$H$8 -> 5 | E25: Go to Event & CPD Tracker ›
B26: SOPs overdue or due for review | D26: =COUNTIF('SOP Library'!$K$5:$K$9,"<>Current") -> 2 | E26: Go to SOP Library ›
B27: Travel items not yet confirmed | D27: =COUNTIF('Travel Planner'!$I$11:$I$20,"<>Booked") -> 3 | E27: Go to Travel Planner ›

Sheet Weekly Report
B1: Weekly Executive Support Report
B2: ="Week ending "&DAY(AsOfDate)&"/"&MONTH(AsOfDate)&"/"&YEAR(AsOfDate)&" · prepared by Ali Puchero, Executive Assistant" -> Week ending 30/10/2026 · prepared by Ali Puchero, Executive Assistant
B4: Snapshot
B5: Metric | C5: This week | D5: Comment
B6: Open tasks | C6: =Dashboard!B6 -> 14 | D6: Includes 2 items waiting on others.
B7: Overdue | C7: =Dashboard!D6 -> 3 | D7: Brightwell letter, SOP-05 review and catering numbers: all chased today.
B8: Total outstanding | C8: =Dashboard!B10 -> 43830 | D8: Includes 4 invoices that are not yet due.
B9: Overdue amount | C9: =Dashboard!D10 -> 23820 | D9: Two accounts escalated to Finance on 27 Oct.
B10: Weighted pipeline | C10: =Dashboard!D14 -> 12330 | D10: Westfield v2 proposal due 31 Oct.
B11: Open meeting actions | C11: =Dashboard!B18 -> 10 | D11: Owners reminded on Thursday.
B12: Webinar attendance rate | C12: =Dashboard!F18 -> 0.875 | D12: Session 3 certificates going out by 3 Nov.
B13: Avg onboarding completion | C13: =Dashboard!H18 -> 0.54166667 | D13: Westfield onboarding started 30 Oct.
B15: Highlights
B16: • Q4 board pack outline approved; financial summary due 2 Nov.
B17: • Sydney trip booked; client dinner, one meeting and the airport taxi still to confirm.
B18: • Pinecrest fully onboarded; Bayview at 7 of 8 steps (tool access pending).
B19: • PM tool research delivered; 14-day trial approved.
B21: Needs your decision
B22: • Approve revised Westfield scope before it goes to the client.
B23: • Confirm attendees for the 14 Nov planning day.
B25: Priorities next week
B26: • Finalise and send the board pack.
B27: • Issue Session 3 CPD certificates.
B28: • Follow up overdue leads and invoices.
B29: • Set up the PM tool trial workspace.

Sheet SOP Library
B1: SOP Library
B2: Register of standard operating procedures with review dates. Status updates automatically from the as-of date.
B4: SOP ID | C4: Title | D4: Category | E4: Owner | F4: Version | G4: Last reviewed | H4: Review cycle (months) | I4: Next review | J4: Days to review | K4: Status | L4: Open
B5: SOP-01 | C5: Executive Inbox Management | D5: Executive support | E5: Ali Puchero (EA) | F5: 1.2 | G5: 46237 | H5: 6 | I5: =EDATE(G5,H5) -> 46421 | J5: =I5-AsOfDate -> 96 | K5: =IF(J5<0,"Overdue",IF(J5<=30,"Due soon","Current")) -> Current | L5: Open SOP-01 ›
B6: SOP-02 | C6: Calendar & Meeting Coordination | D6: Executive support | E6: Ali Puchero (EA) | F6: 1.1 | G6: 46157 | H6: 6 | I6: =EDATE(G6,H6) -> 46341 | J6: =I6-AsOfDate -> 16 | K6: =IF(J6<0,"Overdue",IF(J6<=30,"Due soon","Current")) -> Due soon | L6: Open SOP-02 ›
B7: SOP-03 | C7: New Client Onboarding | D7: Client operations | E7: Ali Puchero (EA) | F7: 1.0 | G7: 46224 | H7: 12 | I7: =EDATE(G7,H7) -> 46589 | J7: =I7-AsOfDate -> 264 | K7: =IF(J7<0,"Overdue",IF(J7<=30,"Due soon","Current")) -> Current | L7: Open SOP-03 ›
B8: SOP-04 | C8: Accounts Receivable Follow-up (Xero) | D8: Accounting admin | E8: Ali Puchero (EA) | F8: 1.3 | G8: 46266 | H8: 6 | I8: =EDATE(G8,H8) -> 46447 | J8: =I8-AsOfDate -> 122 | K8: =IF(J8<0,"Overdue",IF(J8<=30,"Due soon","Current")) -> Current | L8: Open SOP-04 ›
B9: SOP-05 | C9: Webinar Delivery & CPD Attendance | D9: Events & training | E9: Ali Puchero (EA) | F9: 1.1 | G9: 46132 | H9: 6 | I9: =EDATE(G9,H9) -> 46315 | J9: =I9-AsOfDate -> -10 | K9: =IF(J9<0,"Overdue",IF(J9<=30,"Due soon","Current")) -> Overdue | L9: Open SOP-05 ›

Sheet SOP-01 Inbox
B1: SOP-01 · Executive Inbox Management
B2: Standard operating procedure · written and maintained by Alliah (Ali) Puchero
B4: Purpose | D4: Keep the executive’s inbox at a manageable level so urgent and client emails are actioned the same day and nothing important is missed.
B5: Scope | D5: The executive’s main mailbox and shared client mailbox. Excludes HR-confidential folders unless delegated in writing.
B6: Trigger / frequency | D6: Twice daily: 8:00 AM and 3:30 PM (executive’s time zone), plus a quick scan before end of day.
B7: Owner | D7: Executive Assistant (Ali Puchero)
B8: Tools | D8: Outlook / Gmail, Microsoft Teams or Slack, Task Tracker tab
B9: Time standard | D9: Client emails acknowledged within 4 business hours; internal within 1 business day.
B11: Procedure
B12: Step | C12: Phase | D12: Action | E12: Standard / detail | F12: Tool | G12: Output / check
B13: =ROW()-12 -> 1 | C13: Prepare | D13: Open the mailbox in Focused / Priority view | E13: Sort by date, newest first. Check flagged items carried over from the last session. | F13: Outlook | G13: Starting view ready
B14: =ROW()-12 -> 2 | C14: Triage | D14: Apply the 4D rule to every new email | E14: Do (under 2 min), Delegate, Defer (schedule it), Delete / archive. Touch each email once. | F14: Outlook | G14: Inbox shows only open items
B15: =ROW()-12 -> 3 | C15: Triage | D15: File into the folder structure | E15: Clients › [Client name]; Internal › Operations / Finance / HR; Projects; Vendors; Newsletters; Receipts. | F15: Outlook rules + folders | G15: Correct folder, consistent naming
B16: =ROW()-12 -> 4 | C16: Action | D16: Draft or send routine replies | E16: Use the approved templates. Drafts that need the executive’s voice go to Drafts with “FOR REVIEW” in the subject. | F16: Outlook templates | G16: Replies sent / drafts queued
B17: =ROW()-12 -> 5 | C17: Action | D17: Convert requests into tasks | E17: Anything taking more than 2 minutes becomes a task with an owner, due date and link to the email. | F17: Task Tracker | G17: Task logged with due date
B18: =ROW()-12 -> 6 | C18: Action | D18: Add meetings and deadlines to the calendar | E18: Accept / propose times per the executive’s preferences; add prep blocks before important meetings. | F18: Outlook Calendar | G18: Calendar updated
B19: =ROW()-12 -> 7 | C19: Communicate | D19: Send the executive a short summary | E19: Three headings: Needs your decision · FYI · Done for you. Max 10 lines. | F19: Teams / Slack | G19: Summary sent
B20: =ROW()-12 -> 8 | C20: Close | D20: End-of-day sweep | E20: Confirm all client emails were acknowledged; carry over flagged items to the next session. | F20: Outlook | G20: Inbox under 15 open items
B22: Quality checks
B23: • | C23: No client email older than 4 business hours without an acknowledgement.
B24: • | C24: Every flagged email has a matching task or calendar entry.
B25: • | C25: Attachments with sensitive data (IDs, bank details) are saved to the secure folder and not forwarded.
B27: When to escalate
B28: • | C28: Legal, complaint or payment-dispute emails: forward to the executive immediately and flag red.
B29: • | C29: Anything mentioning a deadline within 24 hours that I cannot action myself.
B31: Templates
B32: Acknowledgement | D32: Hi [Name], Thank you for your email. I’ve passed this to [Executive] and will come back to you by [day/time] with an update. Kind regards, Ali Puchero | Executive Assistant
B33: Summary to executive | D33: NEEDS YOUR DECISION: … FYI: … DONE FOR YOU: …
B35: Revision history
B36: Version | C36: Date | D36: Change | E36: Approved by
B37: 1.0 | C37: 46062 | D37: First version | E37: CEO
B38: 1.1 | C38: 46146 | D38: Added folder structure and 4D rule | E38: CEO
B39: 1.2 | C39: 46237 | D39: Added end-of-day sweep and templates | E39: CEO

Sheet SOP-02 Meetings
B1: SOP-02 · Calendar & Meeting Coordination
B2: Standard operating procedure · written and maintained by Alliah (Ali) Puchero
B4: Purpose | D4: Make every meeting the executive attends well-timed, prepared and followed through, with actions captured and owned.
B5: Scope | D5: Internal, client and board meetings on the executive’s calendar, in person or online.
B6: Trigger / frequency | D6: Any meeting request; weekly calendar review every Friday afternoon.
B7: Owner | D7: Executive Assistant (Ali Puchero)
B8: Tools | D8: Outlook / Google Calendar, Zoom, MS Teams, Google Meet, Notion, Meeting Actions tab
B9: Time standard | D9: Invites sent within 1 business day of request; notes and actions circulated within 24 hours of the meeting.
B11: Procedure
B12: Step | C12: Phase | D12: Action | E12: Standard / detail | F12: Tool | G12: Output / check
B13: =ROW()-12 -> 1 | C13: Plan | D13: Confirm purpose, attendees, duration and format | E13: Check the executive’s preferences: no meetings before 9:00, 15-minute buffers, focus blocks protected. | F13: Calendar | G13: Meeting brief agreed
B14: =ROW()-12 -> 2 | C14: Schedule | D14: Find a time and send the invite | E14: Offer 2–3 options across time zones; include agenda, platform link and dial-in in the invite. | F14: Calendly / Outlook | G14: Invite sent
B15: =ROW()-12 -> 3 | C15: Prepare | D15: Confirm attendance 48 hours before | E15: Chase non-responses; update status to Confirmed or To Confirm. | F15: Email / Notion | G15: Attendance confirmed
B16: =ROW()-12 -> 4 | C16: Prepare | D16: Assemble the meeting pack | E16: Agenda, previous actions, decks and data, saved in the meeting’s folder and linked in the invite. | F16: Google Drive / OneDrive | G16: Pack shared 24 h before
B17: =ROW()-12 -> 5 | C17: Run | D17: Take notes during the meeting | E17: Capture decisions, owners and due dates using the notes template. | F17: Notion / Word | G17: Notes drafted
B18: =ROW()-12 -> 6 | C18: Follow up | D18: Circulate notes and log actions | E18: Send notes within 24 hours; log each action in Meeting Actions with owner and due date. | F18: Email + Meeting Actions | G18: Actions tracked
B19: =ROW()-12 -> 7 | C19: Follow up | D19: Chase open actions | E19: Review open actions every Monday; remind owners 2 days before due dates. | F19: Meeting Actions | G19: Overdue actions = 0
B21: Quality checks
B22: • | C22: Every external meeting has a link, a dial-in and the correct time zone in the invite.
B23: • | C23: No back-to-back meetings over 2 hours without a break.
B24: • | C24: Every action has one owner and a due date.
B26: When to escalate
B27: • | C27: Clashes involving board, investor or client meetings: ask the executive before moving anything.
B29: Templates
B30: Invite text | D30: Purpose: … Agenda: 1) … 2) … 3) … Pre-read: [link] Join: [Zoom / Teams link] · Meeting ID … · Passcode …
B32: Revision history
B33: Version | C33: Date | D33: Change | E33: Approved by
B34: 1.0 | C34: 46041 | D34: First version | E34: CEO
B35: 1.1 | C35: 46157 | D35: Added 48-hour confirmation step | E35: CEO

Sheet SOP-03 Onboarding
B1: SOP-03 · New Client Onboarding
B2: Standard operating procedure · written and maintained by Alliah (Ali) Puchero
B4: Purpose | D4: Give every new client a consistent, professional first experience and make sure their records are complete before work begins.
B5: Scope | D5: All new clients from signed proposal to kick-off call.
B6: Trigger / frequency | D6: Proposal marked Won in the CRM.
B7: Owner | D7: Executive Assistant (Ali Puchero)
B8: Tools | D8: GoHighLevel / HubSpot CRM, Xero, Google Drive, email, Onboarding Tracker tab
B9: Time standard | D9: Welcome email same day; onboarding complete within 10 business days.
B11: Procedure
B12: Step | C12: Phase | D12: Action | E12: Standard / detail | F12: Tool | G12: Output / check
B13: =ROW()-12 -> 1 | C13: Welcome | D13: Send the welcome email and onboarding pack | E13: Personalise the template; attach engagement letter and client information form. | F13: Email | G13: Welcome email sent
B14: =ROW()-12 -> 2 | C14: Documents | D14: Collect the signed engagement letter | E14: Chase after 3 business days; save the signed copy as “[Client] – Engagement Letter – [date]”. | F14: Email / e-signature | G14: Signed letter on file
B15: =ROW()-12 -> 3 | C15: Documents | D15: Collect identification (where required) | E15: Request securely; never by plain email reply. Record the ID check date. | F15: Secure upload | G15: ID verified
B16: =ROW()-12 -> 4 | C16: Systems | D16: Create / update the CRM record | E16: Contact details, service, stage “Won”, account owner and next step. | F16: CRM | G16: CRM record complete
B17: =ROW()-12 -> 5 | C17: Systems | D17: Create the client contact in Xero | E17: Billing contact, payment terms and invoice email address. | F17: Xero | G17: Xero contact ready
B18: =ROW()-12 -> 6 | C18: Systems | D18: Set up the client folder | E18: Standard structure: 01 Admin · 02 Correspondence · 03 Working files · 04 Deliverables. | F18: Google Drive | G18: Folder shared
B19: =ROW()-12 -> 7 | C19: Kick-off | D19: Book the kick-off call | E19: Offer three times; include agenda and attendee list. | F19: Calendly | G19: Kick-off booked
B20: =ROW()-12 -> 8 | C20: Kick-off | D20: Grant tool access and confirm | E20: Invite the client to shared tools; confirm they can log in before the call. | F20: Various | G20: Access confirmed
B22: Quality checks
B23: • | C23: Onboarding Tracker shows 100% before any billable work starts.
B24: • | C24: Client name spelled identically in CRM, Xero and folder name.
B26: When to escalate
B27: • | C27: Engagement letter unsigned after 7 business days: inform the account manager.
B28: • | C28: ID documents that look altered or expired.
B30: Revision history
B31: Version | C31: Date | D31: Change | E31: Approved by
B32: 1.0 | C32: 46224 | D32: First version | E32: Operations Manager

Sheet SOP-04 AR Follow-up
B1: SOP-04 · Accounts Receivable Follow-up (Xero)
B2: Standard operating procedure · written and maintained by Alliah (Ali) Puchero
B4: Purpose | D4: Reduce overdue invoices through consistent, polite and well-documented follow-up, while protecting client relationships.
B5: Scope | D5: All open customer invoices in Xero. Excludes invoices under formal dispute (handled by Finance).
B6: Trigger / frequency | D6: Every Monday and Thursday morning.
B7: Owner | D7: Executive Assistant (Ali Puchero)
B8: Tools | D8: Xero (Aged Receivables report, invoice reminders), email, phone, AR Tracker tab
B9: Time standard | D9: Every overdue invoice has a logged contact within the last 7 days.
B11: Procedure
B12: Step | C12: Phase | D12: Action | E12: Standard / detail | F12: Tool | G12: Output / check
B13: =ROW()-12 -> 1 | C13: Review | D13: Run the Aged Receivables report in Xero | E13: Report date = today; group by contact. Export or update the AR Tracker. | F13: Xero | G13: Aging list current
B14: =ROW()-12 -> 2 | C14: Review | D14: Check for payments not yet reconciled | E14: Look at bank feed lines and remittance emails before chasing anyone. | F14: Xero bank feed | G14: No client chased for a paid invoice
B15: =ROW()-12 -> 3 | C15: Follow up | D15: 1–7 days overdue: friendly reminder | E15: Template “Reminder 1”, invoice attached, payment link included. | F15: Email / Xero | G15: Reminder 1 sent
B16: =ROW()-12 -> 4 | C16: Follow up | D16: 8–21 days overdue: firm reminder | E16: Template “Reminder 2”; ask for an expected payment date. | F16: Email | G16: Payment date requested
B17: =ROW()-12 -> 5 | C17: Follow up | D17: 22–45 days overdue: phone call | E17: Use the call script; log the promised date and the person spoken to. | F17: Phone | G17: Call logged
B18: =ROW()-12 -> 6 | C18: Escalate | D18: Over 45 days: escalate to the manager | E18: Summarise the history (dates, contacts, promises) in one email. | F18: Email | G18: Escalation sent
B19: =ROW()-12 -> 7 | C19: Record | D19: Update the tracker and Xero notes | E19: Last contact date, stage, promised date and any part payments. | F19: AR Tracker + Xero history | G19: Records up to date
B21: Quality checks
B22: • | C22: Never send a reminder without checking for an unreconciled payment first.
B23: • | C23: Tone stays courteous at every stage; no threats or fees unless approved by Finance.
B24: • | C24: Promised payment dates are diarised and checked the following day.
B26: When to escalate
B27: • | C27: Client disputes the amount or the work: stop reminders and pass to Finance the same day.
B28: • | C28: Any invoice over 45 days or over $10,000 overdue.
B30: Templates
B31: Reminder 1 | D31: Hi [Name], A quick reminder that invoice [#] for [$amount] was due on [date]. I’ve attached a copy for convenience. If it’s already been paid, thank you, and please disregard this note. Kind regards, Ali
B32: Reminder 2 | D32: Hi [Name], Invoice [#] for [$amount] is now [x] days overdue. Could you let me know when we can expect payment? I’m happy to resend anything you need. Kind regards, Ali
B33: Call script | D33: Introduce yourself → confirm the invoice was received → ask if anything is holding it up → agree a payment date → confirm by email the same day.
B35: Revision history
B36: Version | C36: Date | D36: Change | E36: Approved by
B37: 1.0 | C37: 45992 | D37: First version | E37: Finance Lead
B38: 1.2 | C38: 46118 | D38: Added unreconciled-payment check | E38: Finance Lead
B39: 1.3 | C39: 46266 | D39: Updated stage thresholds and call script | E39: Finance Lead

Sheet SOP-05 Webinars & CPD
B1: SOP-05 · Webinar Delivery & CPD Attendance
B2: Standard operating procedure · written and maintained by Alliah (Ali) Puchero
B4: Purpose | D4: Deliver training webinars smoothly and keep accurate attendance records so CPD certificates are issued only to eligible attendees.
B5: Scope | D5: All live training sessions that carry CPD credit.
B6: Trigger / frequency | D6: Each scheduled training session (registration opens 3 weeks before).
B7: Owner | D7: Executive Assistant (Ali Puchero)
B8: Tools | D8: Zoom (registration + attendance report), GoHighLevel, Canva (certificates), MS Excel, Event & CPD Tracker tab
B9: Time standard | D9: Certificates issued within 3 business days of the session.
B11: Procedure
B12: Step | C12: Phase | D12: Action | E12: Standard / detail | F12: Tool | G12: Output / check
B13: =ROW()-12 -> 1 | C13: Before | D13: Open registration and confirm each registrant | E13: Confirmation email with date, time zone, joining link and CPD requirements. | F13: Zoom / GHL | G13: Confirmation sent
B14: =ROW()-12 -> 2 | C14: Before | D14: Send reminders | E14: 7 days, 1 day and 1 hour before. Remind attendees that cameras must stay on for CPD. | F14: GHL automation | G14: Reminders sent
B15: =ROW()-12 -> 3 | C15: During | D15: Host support and spot-checks | E15: Admit attendees, manage chat, record camera-on spot checks every 15 minutes. | F15: Zoom | G15: Spot-check log
B16: =ROW()-12 -> 4 | C16: After | D16: Download the attendance report | E16: Minutes attended per person; match to registrations by email address. | F16: Zoom report | G16: Tracker updated
B17: =ROW()-12 -> 5 | C17: After | D17: Assess CPD eligibility | E17: Eligible = attended ≥ minimum % and camera-on ≥ requirement (set in the tracker). | F17: Event & CPD Tracker | G17: Eligibility list
B18: =ROW()-12 -> 6 | C18: After | D18: Issue certificates and follow-ups | E18: Certificates to eligible attendees; recording and rebooking options to others. | F18: Canva / email | G18: Certificates sent
B20: Quality checks
B21: • | C21: Names on certificates match registration records exactly.
B22: • | C22: Eligibility thresholds match the program’s published CPD rules.
B24: When to escalate
B25: • | C25: Attendee disputes their eligibility: share the attendance record and refer to the program lead.
B27: Revision history
B28: Version | C28: Date | D28: Change | E28: Approved by
B29: 1.0 | C29: 45943 | D29: First version | E29: Program Lead
B30: 1.1 | C30: 46132 | D30: Added camera-on spot checks | E30: Program Lead

Sheet Task Tracker
B1: Task Tracker
B2: Every request in one list, with priority, due date and an automatic health flag.
B4: ID | C4: Task | D4: Project / area | E4: Requested by | F4: Owner | G4: Priority | H4: Start | I4: Due | J4: Status | K4: % complete | L4: Days left | M4: Health | N4: Notes
B5: T-001 | C5: Prepare Q4 board pack (agenda, deck, financial summary) | D5: Board meeting | E5: CEO | F5: Ali | G5: High | H5: 46315 | I5: 46330 | J5: In progress | K5: 0.6 | L5: =IF(J5="Completed","",I5-AsOfDate) -> 5 | M5: =IF(J5="Completed","Done",IF(I5<AsOfDate,"Overdue",IF(I5-AsOfDate<=3,"Due soon","On track"))) -> On track | N5: Finance summary due from Finance Lead on 2 Nov
B6: T-002 | C6: Book flights and hotel for Sydney client visit | D6: Travel | E6: CEO | F6: Ali | G6: High | H6: 46317 | I6: 46324 | J6: Completed | K6: 1 | L6: =IF(J6="Completed","",I6-AsOfDate) | M6: =IF(J6="Completed","Done",IF(I6<AsOfDate,"Overdue",IF(I6-AsOfDate<=3,"Due soon","On track"))) -> Done | N6: See Travel Planner
B7: T-003 | C7: Send onboarding pack to Harbourline Accounting | D7: Client onboarding | E7: Account Manager | F7: Ali | G7: High | H7: 46322 | I7: 46323 | J7: Completed | K7: 1 | L7: =IF(J7="Completed","",I7-AsOfDate) | M7: =IF(J7="Completed","Done",IF(I7<AsOfDate,"Overdue",IF(I7-AsOfDate<=3,"Due soon","On track"))) -> Done
B8: T-004 | C8: Chase signed engagement letter: Brightwell Dental | D8: Client onboarding | E8: Account Manager | F8: Ali | G8: High | H8: 46319 | I8: 46324 | J8: Waiting on others | K8: 0.5 | L8: =IF(J8="Completed","",I8-AsOfDate) -> -1 | M8: =IF(J8="Completed","Done",IF(I8<AsOfDate,"Overdue",IF(I8-AsOfDate<=3,"Due soon","On track"))) -> Overdue | N8: Reminder sent 27 Oct
B9: T-005 | C9: Update CRM stages after pipeline meeting | D9: CRM | E9: Sales Lead | F9: Ali | G9: Medium | H9: 46323 | I9: 46325 | J9: In progress | K9: 0.4 | L9: =IF(J9="Completed","",I9-AsOfDate) -> 0 | M9: =IF(J9="Completed","Done",IF(I9<AsOfDate,"Overdue",IF(I9-AsOfDate<=3,"Due soon","On track"))) -> Due soon
B10: T-006 | C10: Reconcile AR tracker against Xero aged receivables | D10: Accounts receivable | E10: Finance Lead | F10: Ali | G10: High | H10: 46324 | I10: 46325 | J10: In progress | K10: 0.7 | L10: =IF(J10="Completed","",I10-AsOfDate) -> 0 | M10: =IF(J10="Completed","Done",IF(I10<AsOfDate,"Overdue",IF(I10-AsOfDate<=3,"Due soon","On track"))) -> Due soon
B11: T-007 | C11: Draft SOP: Client offboarding | D11: Operations | E11: Operations Manager | F11: Ali | G11: Medium | H11: 46310 | I11: 46332 | J11: In progress | K11: 0.3 | L11: =IF(J11="Completed","",I11-AsOfDate) -> 7 | M11: =IF(J11="Completed","Done",IF(I11<AsOfDate,"Overdue",IF(I11-AsOfDate<=3,"Due soon","On track"))) -> On track | N11: Outline approved
B12: T-008 | C12: Review and update SOP-05 (Webinars & CPD) | D12: Operations | E12: Program Lead | F12: Ali | G12: Medium | H12: 46315 | I12: 46322 | J12: Not started | K12: 0 | L12: =IF(J12="Completed","",I12-AsOfDate) -> -3 | M12: =IF(J12="Completed","Done",IF(I12<AsOfDate,"Overdue",IF(I12-AsOfDate<=3,"Due soon","On track"))) -> Overdue | N12: Review date passed
B13: T-009 | C13: Schedule November 1:1s with team leads | D13: Calendar | E13: CEO | F13: Ali | G13: Medium | H13: 46321 | I13: 46328 | J13: Not started | K13: 0 | L13: =IF(J13="Completed","",I13-AsOfDate) -> 3 | M13: =IF(J13="Completed","Done",IF(I13<AsOfDate,"Overdue",IF(I13-AsOfDate<=3,"Due soon","On track"))) -> Due soon
B14: T-010 | C14: Issue CPD certificates for Session 3 | D14: Training program | E14: Program Lead | F14: Ali | G14: High | H14: 46324 | I14: 46329 | J14: In progress | K14: 0.5 | L14: =IF(J14="Completed","",I14-AsOfDate) -> 4 | M14: =IF(J14="Completed","Done",IF(I14<AsOfDate,"Overdue",IF(I14-AsOfDate<=3,"Due soon","On track"))) -> On track | N14: Waiting on 2 camera-log checks
B15: T-011 | C15: Set up client folder: Kestrel Logistics | D15: Client onboarding | E15: Account Manager | F15: Ali | G15: Low | H15: 46323 | I15: 46331 | J15: Not started | K15: 0 | L15: =IF(J15="Completed","",I15-AsOfDate) -> 6 | M15: =IF(J15="Completed","Done",IF(I15<AsOfDate,"Overdue",IF(I15-AsOfDate<=3,"Due soon","On track"))) -> On track
B16: T-012 | C16: Monthly KPI report for October | D16: Reporting | E16: CEO | F16: Ali | G16: Medium | H16: 46325 | I16: 46329 | J16: Not started | K16: 0 | L16: =IF(J16="Completed","",I16-AsOfDate) -> 4 | M16: =IF(J16="Completed","Done",IF(I16<AsOfDate,"Overdue",IF(I16-AsOfDate<=3,"Due soon","On track"))) -> On track
B17: T-013 | C17: Renew software subscriptions (Zoom, Canva) | D17: Admin | E17: Operations Manager | F17: Ali | G17: Low | H17: 46305 | I17: 46320 | J17: Completed | K17: 1 | L17: =IF(J17="Completed","",I17-AsOfDate) | M17: =IF(J17="Completed","Done",IF(I17<AsOfDate,"Overdue",IF(I17-AsOfDate<=3,"Due soon","On track"))) -> Done
B18: T-014 | C18: Compile research: project management tools | D18: Research | E18: Operations Manager | F18: Ali | G18: Medium | H18: 46307 | I18: 46318 | J18: Completed | K18: 1 | L18: =IF(J18="Completed","",I18-AsOfDate) | M18: =IF(J18="Completed","Done",IF(I18<AsOfDate,"Overdue",IF(I18-AsOfDate<=3,"Due soon","On track"))) -> Done | N18: See Research Brief
B19: T-015 | C19: Prepare agenda: quarterly client review (Northgate) | D19: Meetings | E19: Account Manager | F19: Ali | G19: Medium | H19: 46322 | I19: 46326 | J19: In progress | K19: 0.5 | L19: =IF(J19="Completed","",I19-AsOfDate) -> 1 | M19: =IF(J19="Completed","Done",IF(I19<AsOfDate,"Overdue",IF(I19-AsOfDate<=3,"Due soon","On track"))) -> Due soon
B20: T-016 | C20: Clean up duplicate contacts in CRM | D20: CRM | E20: Sales Lead | F20: Ali | G20: Low | H20: 46296 | I20: 46340 | J20: In progress | K20: 0.25 | L20: =IF(J20="Completed","",I20-AsOfDate) -> 15 | M20: =IF(J20="Completed","Done",IF(I20<AsOfDate,"Overdue",IF(I20-AsOfDate<=3,"Due soon","On track"))) -> On track | N20: ~40 duplicates found
B21: T-017 | C21: Collect expense receipts for October | D21: Admin | E21: Finance Lead | F21: Ali | G21: Low | H21: 46320 | I21: 46328 | J21: Waiting on others | K21: 0.5 | L21: =IF(J21="Completed","",I21-AsOfDate) -> 3 | M21: =IF(J21="Completed","Done",IF(I21<AsOfDate,"Overdue",IF(I21-AsOfDate<=3,"Due soon","On track"))) -> Due soon
B22: T-018 | C22: Confirm venue catering for team planning day | D22: Events | E22: Operations Manager | F22: Ali | G22: Medium | H22: 46316 | I22: 46323 | J22: Waiting on others | K22: 0.8 | L22: =IF(J22="Completed","",I22-AsOfDate) -> -2 | M22: =IF(J22="Completed","Done",IF(I22<AsOfDate,"Overdue",IF(I22-AsOfDate<=3,"Due soon","On track"))) -> Overdue | N22: Venue to confirm numbers

Sheet AR Tracker
B1: Accounts Receivable Tracker
B2: Outstanding invoices with automatic aging, follow-up stage and next action date. Mirrors SOP-04.
B4: Invoice # | C4: Client | D4: Billing email | E4: Issue date | F4: Terms (days) | G4: Due date | H4: Amount | I4: Paid | J4: Balance | K4: Days overdue | L4: Aging bucket | M4: Last contact | N4: Follow-up stage | O4: Next action | P4: Status
B5: INV-1041 | C5: Harbourline Accounting | D5: accounts@harbourlineacc.example.com | E5: 46266 | F5: 14 | G5: =E5+F5 -> 46280 | H5: 2450 | I5: 2450 | J5: =H5-I5 -> 0 | K5: =IF(J5<=0,0,MAX(0,AsOfDate-G5)) -> 0 | L5: =IF(J5<=0,"Paid",IF(K5=0,"Current",IF(K5<=30,"1-30 days",IF(K5<=60,"31-60 days",IF(K5<=90,"61-90 days","90+ days"))))) -> Paid | M5: 46277 | N5: =IF(J5<=0,"Closed",IF(K5=0,"Not yet due",IF(K5<=7,"Reminder 1 (friendly)",IF(K5<=21,"Reminder 2 (firm)",IF(K5<=45,"Phone call","Escalate to manager"))))) -> Closed | O5: =IF(J5<=0,"",IF(K5=0,G5,IF(M5="",AsOfDate,MAX(AsOfDate,M5+7)))) | P5: =IF(J5<=0,"Paid",IF(I5>0,"Part-paid",IF(K5>0,"Overdue","Open"))) -> Paid
B6: INV-1042 | C6: Northgate Advisory | D6: accounts@northgateadvis.example.com | E6: 46270 | F6: 30 | G6: =E6+F6 -> 46300 | H6: 5800 | I6: 0 | J6: =H6-I6 -> 5800 | K6: =IF(J6<=0,0,MAX(0,AsOfDate-G6)) -> 25 | L6: =IF(J6<=0,"Paid",IF(K6=0,"Current",IF(K6<=30,"1-30 days",IF(K6<=60,"31-60 days",IF(K6<=90,"61-90 days","90+ days"))))) -> 1-30 days | M6: 46309 | N6: =IF(J6<=0,"Closed",IF(K6=0,"Not yet due",IF(K6<=7,"Reminder 1 (friendly)",IF(K6<=21,"Reminder 2 (firm)",IF(K6<=45,"Phone call","Escalate to manager"))))) -> Phone call | O6: =IF(J6<=0,"",IF(K6=0,G6,IF(M6="",AsOfDate,MAX(AsOfDate,M6+7)))) -> 46325 | P6: =IF(J6<=0,"Paid",IF(I6>0,"Part-paid",IF(K6>0,"Overdue","Open"))) -> Overdue
B7: INV-1043 | C7: Brightwell Dental | D7: accounts@brightwelldent.example.com | E7: 46275 | F7: 14 | G7: =E7+F7 -> 46289 | H7: 1320 | I7: 0 | J7: =H7-I7 -> 1320 | K7: =IF(J7<=0,0,MAX(0,AsOfDate-G7)) -> 36 | L7: =IF(J7<=0,"Paid",IF(K7=0,"Current",IF(K7<=30,"1-30 days",IF(K7<=60,"31-60 days",IF(K7<=90,"61-90 days","90+ days"))))) -> 31-60 days | M7: 46317 | N7: =IF(J7<=0,"Closed",IF(K7=0,"Not yet due",IF(K7<=7,"Reminder 1 (friendly)",IF(K7<=21,"Reminder 2 (firm)",IF(K7<=45,"Phone call","Escalate to manager"))))) -> Phone call | O7: =IF(J7<=0,"",IF(K7=0,G7,IF(M7="",AsOfDate,MAX(AsOfDate,M7+7)))) -> 46325 | P7: =IF(J7<=0,"Paid",IF(I7>0,"Part-paid",IF(K7>0,"Overdue","Open"))) -> Overdue
B8: INV-1044 | C8: Kestrel Logistics | D8: accounts@kestrellogisti.example.com | E8: 46280 | F8: 30 | G8: =E8+F8 -> 46310 | H8: 3975 | I8: 2000 | J8: =H8-I8 -> 1975 | K8: =IF(J8<=0,0,MAX(0,AsOfDate-G8)) -> 15 | L8: =IF(J8<=0,"Paid",IF(K8=0,"Current",IF(K8<=30,"1-30 days",IF(K8<=60,"31-60 days",IF(K8<=90,"61-90 days","90+ days"))))) -> 1-30 days | M8: 46322 | N8: =IF(J8<=0,"Closed",IF(K8=0,"Not yet due",IF(K8<=7,"Reminder 1 (friendly)",IF(K8<=21,"Reminder 2 (firm)",IF(K8<=45,"Phone call","Escalate to manager"))))) -> Reminder 2 (firm) | O8: =IF(J8<=0,"",IF(K8=0,G8,IF(M8="",AsOfDate,MAX(AsOfDate,M8+7)))) -> 46329 | P8: =IF(J8<=0,"Paid",IF(I8>0,"Part-paid",IF(K8>0,"Overdue","Open"))) -> Part-paid
B9: INV-1045 | C9: Summit Property Group | D9: accounts@summitproperty.example.com | E9: 46285 | F9: 14 | G9: =E9+F9 -> 46299 | H9: 860 | I9: 0 | J9: =H9-I9 -> 860 | K9: =IF(J9<=0,0,MAX(0,AsOfDate-G9)) -> 26 | L9: =IF(J9<=0,"Paid",IF(K9=0,"Current",IF(K9<=30,"1-30 days",IF(K9<=60,"31-60 days",IF(K9<=90,"61-90 days","90+ days"))))) -> 1-30 days | N9: =IF(J9<=0,"Closed",IF(K9=0,"Not yet due",IF(K9<=7,"Reminder 1 (friendly)",IF(K9<=21,"Reminder 2 (firm)",IF(K9<=45,"Phone call","Escalate to manager"))))) -> Phone call | O9: =IF(J9<=0,"",IF(K9=0,G9,IF(M9="",AsOfDate,MAX(AsOfDate,M9+7)))) -> 46325 | P9: =IF(J9<=0,"Paid",IF(I9>0,"Part-paid",IF(K9>0,"Overdue","Open"))) -> Overdue
B10: INV-1046 | C10: Oakridge Legal | D10: accounts@oakridgelegal.example.com | E10: 46290 | F10: 30 | G10: =E10+F10 -> 46320 | H10: 7200 | I10: 7200 | J10: =H10-I10 -> 0 | K10: =IF(J10<=0,0,MAX(0,AsOfDate-G10)) -> 0 | L10: =IF(J10<=0,"Paid",IF(K10=0,"Current",IF(K10<=30,"1-30 days",IF(K10<=60,"31-60 days",IF(K10<=90,"61-90 days","90+ days"))))) -> Paid | M10: 46315 | N10: =IF(J10<=0,"Closed",IF(K10=0,"Not yet due",IF(K10<=7,"Reminder 1 (friendly)",IF(K10<=21,"Reminder 2 (firm)",IF(K10<=45,"Phone call","Escalate to manager"))))) -> Closed | O10: =IF(J10<=0,"",IF(K10=0,G10,IF(M10="",AsOfDate,MAX(AsOfDate,M10+7)))) | P10: =IF(J10<=0,"Paid",IF(I10>0,"Part-paid",IF(K10>0,"Overdue","Open"))) -> Paid
B11: INV-1047 | C11: Bluefin Consulting | D11: accounts@bluefinconsult.example.com | E11: 46252 | F11: 14 | G11: =E11+F11 -> 46266 | H11: 2150 | I11: 0 | J11: =H11-I11 -> 2150 | K11: =IF(J11<=0,0,MAX(0,AsOfDate-G11)) -> 59 | L11: =IF(J11<=0,"Paid",IF(K11=0,"Current",IF(K11<=30,"1-30 days",IF(K11<=60,"31-60 days",IF(K11<=90,"61-90 days","90+ days"))))) -> 31-60 days | M11: 46304 | N11: =IF(J11<=0,"Closed",IF(K11=0,"Not yet due",IF(K11<=7,"Reminder 1 (friendly)",IF(K11<=21,"Reminder 2 (firm)",IF(K11<=45,"Phone call","Escalate to manager"))))) -> Escalate to manager | O11: =IF(J11<=0,"",IF(K11=0,G11,IF(M11="",AsOfDate,MAX(AsOfDate,M11+7)))) -> 46325 | P11: =IF(J11<=0,"Paid",IF(I11>0,"Part-paid",IF(K11>0,"Overdue","Open"))) -> Overdue
B12: INV-1048 | C12: Cedar & Co. Bookkeeping | D12: accounts@cedarcobookkee.example.com | E12: 46296 | F12: 14 | G12: =E12+F12 -> 46310 | H12: 990 | I12: 0 | J12: =H12-I12 -> 990 | K12: =IF(J12<=0,0,MAX(0,AsOfDate-G12)) -> 15 | L12: =IF(J12<=0,"Paid",IF(K12=0,"Current",IF(K12<=30,"1-30 days",IF(K12<=60,"31-60 days",IF(K12<=90,"61-90 days","90+ days"))))) -> 1-30 days | M12: 46315 | N12: =IF(J12<=0,"Closed",IF(K12=0,"Not yet due",IF(K12<=7,"Reminder 1 (friendly)",IF(K12<=21,"Reminder 2 (firm)",IF(K12<=45,"Phone call","Escalate to manager"))))) -> Reminder 2 (firm) | O12: =IF(J12<=0,"",IF(K12=0,G12,IF(M12="",AsOfDate,MAX(AsOfDate,M12+7)))) -> 46325 | P12: =IF(J12<=0,"Paid",IF(I12>0,"Part-paid",IF(K12>0,"Overdue","Open"))) -> Overdue
B13: INV-1049 | C13: Harbourline Accounting | D13: accounts@harbourlineacc.example.com | E13: 46296 | F13: 14 | G13: =E13+F13 -> 46310 | H13: 2450 | I13: 0 | J13: =H13-I13 -> 2450 | K13: =IF(J13<=0,0,MAX(0,AsOfDate-G13)) -> 15 | L13: =IF(J13<=0,"Paid",IF(K13=0,"Current",IF(K13<=30,"1-30 days",IF(K13<=60,"31-60 days",IF(K13<=90,"61-90 days","90+ days"))))) -> 1-30 days | M13: 46324 | N13: =IF(J13<=0,"Closed",IF(K13=0,"Not yet due",IF(K13<=7,"Reminder 1 (friendly)",IF(K13<=21,"Reminder 2 (firm)",IF(K13<=45,"Phone call","Escalate to manager"))))) -> Reminder 2 (firm) | O13: =IF(J13<=0,"",IF(K13=0,G13,IF(M13="",AsOfDate,MAX(AsOfDate,M13+7)))) -> 46331 | P13: =IF(J13<=0,"Paid",IF(I13>0,"Part-paid",IF(K13>0,"Overdue","Open"))) -> Overdue
B14: INV-1050 | C14: Northgate Advisory | D14: accounts@northgateadvis.example.com | E14: 46301 | F14: 30 | G14: =E14+F14 -> 46331 | H14: 5800 | I14: 0 | J14: =H14-I14 -> 5800 | K14: =IF(J14<=0,0,MAX(0,AsOfDate-G14)) -> 0 | L14: =IF(J14<=0,"Paid",IF(K14=0,"Current",IF(K14<=30,"1-30 days",IF(K14<=60,"31-60 days",IF(K14<=90,"61-90 days","90+ days"))))) -> Current | N14: =IF(J14<=0,"Closed",IF(K14=0,"Not yet due",IF(K14<=7,"Reminder 1 (friendly)",IF(K14<=21,"Reminder 2 (firm)",IF(K14<=45,"Phone call","Escalate to manager"))))) -> Not yet due | O14: =IF(J14<=0,"",IF(K14=0,G14,IF(M14="",AsOfDate,MAX(AsOfDate,M14+7)))) -> 46331 | P14: =IF(J14<=0,"Paid",IF(I14>0,"Part-paid",IF(K14>0,"Overdue","Open"))) -> Open
B15: INV-1051 | C15: Riverstone Clinics | D15: accounts@riverstoneclin.example.com | E15: 46231 | F15: 30 | G15: =E15+F15 -> 46261 | H15: 4300 | I15: 0 | J15: =H15-I15 -> 4300 | K15: =IF(J15<=0,0,MAX(0,AsOfDate-G15)) -> 64 | L15: =IF(J15<=0,"Paid",IF(K15=0,"Current",IF(K15<=30,"1-30 days",IF(K15<=60,"31-60 days",IF(K15<=90,"61-90 days","90+ days"))))) -> 61-90 days | M15: 46296 | N15: =IF(J15<=0,"Closed",IF(K15=0,"Not yet due",IF(K15<=7,"Reminder 1 (friendly)",IF(K15<=21,"Reminder 2 (firm)",IF(K15<=45,"Phone call","Escalate to manager"))))) -> Escalate to manager | O15: =IF(J15<=0,"",IF(K15=0,G15,IF(M15="",AsOfDate,MAX(AsOfDate,M15+7)))) -> 46325 | P15: =IF(J15<=0,"Paid",IF(I15>0,"Part-paid",IF(K15>0,"Overdue","Open"))) -> Overdue
B16: INV-1052 | C16: Brightwell Dental | D16: accounts@brightwelldent.example.com | E16: 46305 | F16: 14 | G16: =E16+F16 -> 46319 | H16: 1320 | I16: 1320 | J16: =H16-I16 -> 0 | K16: =IF(J16<=0,0,MAX(0,AsOfDate-G16)) -> 0 | L16: =IF(J16<=0,"Paid",IF(K16=0,"Current",IF(K16<=30,"1-30 days",IF(K16<=60,"31-60 days",IF(K16<=90,"61-90 days","90+ days"))))) -> Paid | M16: 46316 | N16: =IF(J16<=0,"Closed",IF(K16=0,"Not yet due",IF(K16<=7,"Reminder 1 (friendly)",IF(K16<=21,"Reminder 2 (firm)",IF(K16<=45,"Phone call","Escalate to manager"))))) -> Closed | O16: =IF(J16<=0,"",IF(K16=0,G16,IF(M16="",AsOfDate,MAX(AsOfDate,M16+7)))) | P16: =IF(J16<=0,"Paid",IF(I16>0,"Part-paid",IF(K16>0,"Overdue","Open"))) -> Paid
B17: INV-1053 | C17: Pinecrest Builders | D17: accounts@pinecrestbuild.example.com | E17: 46309 | F17: 30 | G17: =E17+F17 -> 46339 | H17: 6150 | I17: 0 | J17: =H17-I17 -> 6150 | K17: =IF(J17<=0,0,MAX(0,AsOfDate-G17)) -> 0 | L17: =IF(J17<=0,"Paid",IF(K17=0,"Current",IF(K17<=30,"1-30 days",IF(K17<=60,"31-60 days",IF(K17<=90,"61-90 days","90+ days"))))) -> Current | N17: =IF(J17<=0,"Closed",IF(K17=0,"Not yet due",IF(K17<=7,"Reminder 1 (friendly)",IF(K17<=21,"Reminder 2 (firm)",IF(K17<=45,"Phone call","Escalate to manager"))))) -> Not yet due | O17: =IF(J17<=0,"",IF(K17=0,G17,IF(M17="",AsOfDate,MAX(AsOfDate,M17+7)))) -> 46339 | P17: =IF(J17<=0,"Paid",IF(I17>0,"Part-paid",IF(K17>0,"Overdue","Open"))) -> Open
B18: INV-1054 | C18: Kestrel Logistics | D18: accounts@kestrellogisti.example.com | E18: 46310 | F18: 14 | G18: =E18+F18 -> 46324 | H18: 3975 | I18: 0 | J18: =H18-I18 -> 3975 | K18: =IF(J18<=0,0,MAX(0,AsOfDate-G18)) -> 1 | L18: =IF(J18<=0,"Paid",IF(K18=0,"Current",IF(K18<=30,"1-30 days",IF(K18<=60,"31-60 days",IF(K18<=90,"61-90 days","90+ days"))))) -> 1-30 days | M18: 46325 | N18: =IF(J18<=0,"Closed",IF(K18=0,"Not yet due",IF(K18<=7,"Reminder 1 (friendly)",IF(K18<=21,"Reminder 2 (firm)",IF(K18<=45,"Phone call","Escalate to manager"))))) -> Reminder 1 (friendly) | O18: =IF(J18<=0,"",IF(K18=0,G18,IF(M18="",AsOfDate,MAX(AsOfDate,M18+7)))) -> 46332 | P18: =IF(J18<=0,"Paid",IF(I18>0,"Part-paid",IF(K18>0,"Overdue","Open"))) -> Overdue
B19: INV-1055 | C19: Summit Property Group | D19: accounts@summitproperty.example.com | E19: 46315 | F19: 14 | G19: =E19+F19 -> 46329 | H19: 860 | I19: 0 | J19: =H19-I19 -> 860 | K19: =IF(J19<=0,0,MAX(0,AsOfDate-G19)) -> 0 | L19: =IF(J19<=0,"Paid",IF(K19=0,"Current",IF(K19<=30,"1-30 days",IF(K19<=60,"31-60 days",IF(K19<=90,"61-90 days","90+ days"))))) -> Current | N19: =IF(J19<=0,"Closed",IF(K19=0,"Not yet due",IF(K19<=7,"Reminder 1 (friendly)",IF(K19<=21,"Reminder 2 (firm)",IF(K19<=45,"Phone call","Escalate to manager"))))) -> Not yet due | O19: =IF(J19<=0,"",IF(K19=0,G19,IF(M19="",AsOfDate,MAX(AsOfDate,M19+7)))) -> 46329 | P19: =IF(J19<=0,"Paid",IF(I19>0,"Part-paid",IF(K19>0,"Overdue","Open"))) -> Open
B20: INV-1056 | C20: Oakridge Legal | D20: accounts@oakridgelegal.example.com | E20: 46317 | F20: 30 | G20: =E20+F20 -> 46347 | H20: 7200 | I20: 0 | J20: =H20-I20 -> 7200 | K20: =IF(J20<=0,0,MAX(0,AsOfDate-G20)) -> 0 | L20: =IF(J20<=0,"Paid",IF(K20=0,"Current",IF(K20<=30,"1-30 days",IF(K20<=60,"31-60 days",IF(K20<=90,"61-90 days","90+ days"))))) -> Current | N20: =IF(J20<=0,"Closed",IF(K20=0,"Not yet due",IF(K20<=7,"Reminder 1 (friendly)",IF(K20<=21,"Reminder 2 (firm)",IF(K20<=45,"Phone call","Escalate to manager"))))) -> Not yet due | O20: =IF(J20<=0,"",IF(K20=0,G20,IF(M20="",AsOfDate,MAX(AsOfDate,M20+7)))) -> 46347 | P20: =IF(J20<=0,"Paid",IF(I20>0,"Part-paid",IF(K20>0,"Overdue","Open"))) -> Open
B23: Aging summary
B24: Bucket | C24: Invoices | D24: Outstanding | E24: % of total
B25: Current | C25: =COUNTIF($L$5:$L$20,B25) -> 4 | D25: =SUMIFS($J$5:$J$20,$L$5:$L$20,B25) -> 20010 | E25: =IFERROR(D25/SUM($J$5:$J$20),0) -> 0.45653662
B26: 1-30 days | C26: =COUNTIF($L$5:$L$20,B26) -> 6 | D26: =SUMIFS($J$5:$J$20,$L$5:$L$20,B26) -> 16050 | E26: =IFERROR(D26/SUM($J$5:$J$20),0) -> 0.36618754
B27: 31-60 days | C27: =COUNTIF($L$5:$L$20,B27) -> 2 | D27: =SUMIFS($J$5:$J$20,$L$5:$L$20,B27) -> 3470 | E27: =IFERROR(D27/SUM($J$5:$J$20),0) -> 0.079169519
B28: 61-90 days | C28: =COUNTIF($L$5:$L$20,B28) -> 1 | D28: =SUMIFS($J$5:$J$20,$L$5:$L$20,B28) -> 4300 | E28: =IFERROR(D28/SUM($J$5:$J$20),0) -> 0.09810632
B29: 90+ days | C29: =COUNTIF($L$5:$L$20,B29) -> 0 | D29: =SUMIFS($J$5:$J$20,$L$5:$L$20,B29) -> 0 | E29: =IFERROR(D29/SUM($J$5:$J$20),0) -> 0
B30: Total outstanding | C30: =SUM(C25:C29) -> 13 | D30: =SUM(D25:D29) -> 43830 | E30: =SUM(E25:E29) -> 1

Sheet CRM Pipeline
B1: CRM Pipeline
B2: Leads by stage with weighted value and an automatic follow-up flag, so no opportunity goes quiet.
B4: Lead ID | C4: Company | D4: Contact (role) | E4: Source | F4: Service interest | G4: Stage | H4: Est. monthly value | I4: Probability | J4: Weighted value | K4: Last contact | L4: Next step | M4: Next step date | N4: Days since contact | O4: Follow-up flag
B5: L-101 | C5: Pinecrest Builders | D5: Director | E5: Referral | F5: Bookkeeping + payroll | G5: Won | H5: 3200 | I5: =IFERROR(INDEX(Lists!$F$2:$F$8,MATCH(G5,Lists!$E$2:$E$8,0)),0) -> 1 | J5: =H5*I5 -> 3200 | K5: 46309 | L5: Onboarding started | M5: 46329 | N5: =AsOfDate-K5 -> 16 | O5: =IF(OR(G5="Won",G5="Lost"),"Closed",IF(M5<AsOfDate,"Overdue",IF(M5=AsOfDate,"Due today",IF(N5>14,"Stale: check in","Scheduled")))) -> Closed
B6: L-102 | C6: Lumen Physio Group | D6: Practice Manager | E6: Website enquiry | F6: Monthly bookkeeping | G6: Proposal sent | H6: 1800 | I6: =IFERROR(INDEX(Lists!$F$2:$F$8,MATCH(G6,Lists!$E$2:$E$8,0)),0) -> 0.6 | J6: =H6*I6 -> 1080 | K6: 46318 | L6: Follow up on proposal | M6: 46325 | N6: =AsOfDate-K6 -> 7 | O6: =IF(OR(G6="Won",G6="Lost"),"Closed",IF(M6<AsOfDate,"Overdue",IF(M6=AsOfDate,"Due today",IF(N6>14,"Stale: check in","Scheduled")))) -> Due today
B7: L-103 | C7: Arbor Creative Studio | D7: Founder | E7: LinkedIn | F7: BAS + advisory | G7: Discovery call | H7: 1200 | I7: =IFERROR(INDEX(Lists!$F$2:$F$8,MATCH(G7,Lists!$E$2:$E$8,0)),0) -> 0.4 | J7: =H7*I7 -> 480 | K7: 46322 | L7: Send discovery notes + quote | M7: 46328 | N7: =AsOfDate-K7 -> 3 | O7: =IF(OR(G7="Won",G7="Lost"),"Closed",IF(M7<AsOfDate,"Overdue",IF(M7=AsOfDate,"Due today",IF(N7>14,"Stale: check in","Scheduled")))) -> Scheduled
B8: L-104 | C8: Westfield Freight | D8: CFO | E8: Event | F8: AR outsourcing | G8: Negotiation | H8: 4500 | I8: =IFERROR(INDEX(Lists!$F$2:$F$8,MATCH(G8,Lists!$E$2:$E$8,0)),0) -> 0.8 | J8: =H8*I8 -> 3600 | K8: 46321 | L8: Revise scope, send v2 | M8: 46326 | N8: =AsOfDate-K8 -> 4 | O8: =IF(OR(G8="Won",G8="Lost"),"Closed",IF(M8<AsOfDate,"Overdue",IF(M8=AsOfDate,"Due today",IF(N8>14,"Stale: check in","Scheduled")))) -> Scheduled
B9: L-105 | C9: Maple & Stone Interiors | D9: Owner | E9: Referral | F9: Xero setup | G9: Contacted | H9: 900 | I9: =IFERROR(INDEX(Lists!$F$2:$F$8,MATCH(G9,Lists!$E$2:$E$8,0)),0) -> 0.2 | J9: =H9*I9 -> 180 | K9: 46303 | L9: Book discovery call | M9: 46317 | N9: =AsOfDate-K9 -> 22 | O9: =IF(OR(G9="Won",G9="Lost"),"Closed",IF(M9<AsOfDate,"Overdue",IF(M9=AsOfDate,"Due today",IF(N9>14,"Stale: check in","Scheduled")))) -> Overdue
B10: L-106 | C10: Coastal Vet Clinic | D10: Practice Owner | E10: Website enquiry | F10: Payroll | G10: New lead | H10: 1100 | I10: =IFERROR(INDEX(Lists!$F$2:$F$8,MATCH(G10,Lists!$E$2:$E$8,0)),0) -> 0.1 | J10: =H10*I10 -> 110 | K10: 46324 | L10: Intro email | M10: 46326 | N10: =AsOfDate-K10 -> 1 | O10: =IF(OR(G10="Won",G10="Lost"),"Closed",IF(M10<AsOfDate,"Overdue",IF(M10=AsOfDate,"Due today",IF(N10>14,"Stale: check in","Scheduled")))) -> Scheduled
B11: L-107 | C11: Granite Tech Pty Ltd | D11: COO | E11: Outreach | F11: Virtual CFO | G11: Proposal sent | H11: 6000 | I11: =IFERROR(INDEX(Lists!$F$2:$F$8,MATCH(G11,Lists!$E$2:$E$8,0)),0) -> 0.6 | J11: =H11*I11 -> 3600 | K11: 46304 | L11: Check proposal received | M11: 46311 | N11: =AsOfDate-K11 -> 21 | O11: =IF(OR(G11="Won",G11="Lost"),"Closed",IF(M11<AsOfDate,"Overdue",IF(M11=AsOfDate,"Due today",IF(N11>14,"Stale: check in","Scheduled")))) -> Overdue
B12: L-108 | C12: Sunbeam Early Learning | D12: Centre Director | E12: Event | F12: Bookkeeping | G12: Discovery call | H12: 1500 | I12: =IFERROR(INDEX(Lists!$F$2:$F$8,MATCH(G12,Lists!$E$2:$E$8,0)),0) -> 0.4 | J12: =H12*I12 -> 600 | K12: 46315 | L12: Confirm requirements | M12: 46330 | N12: =AsOfDate-K12 -> 10 | O12: =IF(OR(G12="Won",G12="Lost"),"Closed",IF(M12<AsOfDate,"Overdue",IF(M12=AsOfDate,"Due today",IF(N12>14,"Stale: check in","Scheduled")))) -> Scheduled
B13: L-109 | C13: Harrow Legal | D13: Partner | E13: Referral | F13: Trust accounting support | G13: Lost | H13: 2800 | I13: =IFERROR(INDEX(Lists!$F$2:$F$8,MATCH(G13,Lists!$E$2:$E$8,0)),0) -> 0 | J13: =H13*I13 -> 0 | K13: 46295 | L13: Closed: chose in-house | N13: =AsOfDate-K13 -> 30 | O13: =IF(OR(G13="Won",G13="Lost"),"Closed",IF(M13<AsOfDate,"Overdue",IF(M13=AsOfDate,"Due today",IF(N13>14,"Stale: check in","Scheduled")))) -> Closed
B14: L-110 | C14: Ironbark Fitness | D14: Owner | E14: LinkedIn | F14: Bookkeeping | G14: Contacted | H14: 700 | I14: =IFERROR(INDEX(Lists!$F$2:$F$8,MATCH(G14,Lists!$E$2:$E$8,0)),0) -> 0.2 | J14: =H14*I14 -> 140 | K14: 46296 | L14: Second follow-up | M14: 46310 | N14: =AsOfDate-K14 -> 29 | O14: =IF(OR(G14="Won",G14="Lost"),"Closed",IF(M14<AsOfDate,"Overdue",IF(M14=AsOfDate,"Due today",IF(N14>14,"Stale: check in","Scheduled")))) -> Overdue
B15: L-111 | C15: Northshore Dental | D15: Practice Manager | E15: Referral | F15: Payroll + BAS | G15: Negotiation | H15: 2600 | I15: =IFERROR(INDEX(Lists!$F$2:$F$8,MATCH(G15,Lists!$E$2:$E$8,0)),0) -> 0.8 | J15: =H15*I15 -> 2080 | K15: 46323 | L15: Agree start date | M15: 46330 | N15: =AsOfDate-K15 -> 2 | O15: =IF(OR(G15="Won",G15="Lost"),"Closed",IF(M15<AsOfDate,"Overdue",IF(M15=AsOfDate,"Due today",IF(N15>14,"Stale: check in","Scheduled")))) -> Scheduled
B16: L-112 | C16: Quill Publishing | D16: Managing Editor | E16: Website enquiry | F16: AR follow-up | G16: New lead | H16: 800 | I16: =IFERROR(INDEX(Lists!$F$2:$F$8,MATCH(G16,Lists!$E$2:$E$8,0)),0) -> 0.1 | J16: =H16*I16 -> 80 | K16: 46325 | L16: Qualify needs | M16: 46328 | N16: =AsOfDate-K16 -> 0 | O16: =IF(OR(G16="Won",G16="Lost"),"Closed",IF(M16<AsOfDate,"Overdue",IF(M16=AsOfDate,"Due today",IF(N16>14,"Stale: check in","Scheduled")))) -> Scheduled
B17: L-113 | C17: Bayview Hotels | D17: Finance Manager | E17: Event | F17: Accounts payable | G17: Won | H17: 5200 | I17: =IFERROR(INDEX(Lists!$F$2:$F$8,MATCH(G17,Lists!$E$2:$E$8,0)),0) -> 1 | J17: =H17*I17 -> 5200 | K17: 46314 | L17: Kick-off booked | M17: 46331 | N17: =AsOfDate-K17 -> 11 | O17: =IF(OR(G17="Won",G17="Lost"),"Closed",IF(M17<AsOfDate,"Overdue",IF(M17=AsOfDate,"Due today",IF(N17>14,"Stale: check in","Scheduled")))) -> Closed
B18: L-114 | C18: Redgum Plumbing | D18: Owner | E18: Outreach | F18: Xero clean-up | G18: Discovery call | H18: 950 | I18: =IFERROR(INDEX(Lists!$F$2:$F$8,MATCH(G18,Lists!$E$2:$E$8,0)),0) -> 0.4 | J18: =H18*I18 -> 380 | K18: 46307 | L18: Send summary | M18: 46314 | N18: =AsOfDate-K18 -> 18 | O18: =IF(OR(G18="Won",G18="Lost"),"Closed",IF(M18<AsOfDate,"Overdue",IF(M18=AsOfDate,"Due today",IF(N18>14,"Stale: check in","Scheduled")))) -> Overdue
B21: Pipeline by stage
B22: Stage | C22: Leads | D22: Est. value | E22: Weighted
B23: New lead | C23: =COUNTIF($G$5:$G$18,B23) -> 2 | D23: =SUMIFS($H$5:$H$18,$G$5:$G$18,B23) -> 1900 | E23: =SUMIFS($J$5:$J$18,$G$5:$G$18,B23) -> 190
B24: Contacted | C24: =COUNTIF($G$5:$G$18,B24) -> 2 | D24: =SUMIFS($H$5:$H$18,$G$5:$G$18,B24) -> 1600 | E24: =SUMIFS($J$5:$J$18,$G$5:$G$18,B24) -> 320
B25: Discovery call | C25: =COUNTIF($G$5:$G$18,B25) -> 3 | D25: =SUMIFS($H$5:$H$18,$G$5:$G$18,B25) -> 3650 | E25: =SUMIFS($J$5:$J$18,$G$5:$G$18,B25) -> 1460
B26: Proposal sent | C26: =COUNTIF($G$5:$G$18,B26) -> 2 | D26: =SUMIFS($H$5:$H$18,$G$5:$G$18,B26) -> 7800 | E26: =SUMIFS($J$5:$J$18,$G$5:$G$18,B26) -> 4680
B27: Negotiation | C27: =COUNTIF($G$5:$G$18,B27) -> 2 | D27: =SUMIFS($H$5:$H$18,$G$5:$G$18,B27) -> 7100 | E27: =SUMIFS($J$5:$J$18,$G$5:$G$18,B27) -> 5680
B28: Won | C28: =COUNTIF($G$5:$G$18,B28) -> 2 | D28: =SUMIFS($H$5:$H$18,$G$5:$G$18,B28) -> 8400 | E28: =SUMIFS($J$5:$J$18,$G$5:$G$18,B28) -> 8400
B29: Lost | C29: =COUNTIF($G$5:$G$18,B29) -> 1 | D29: =SUMIFS($H$5:$H$18,$G$5:$G$18,B29) -> 2800 | E29: =SUMIFS($J$5:$J$18,$G$5:$G$18,B29) -> 0
B30: Total | C30: =SUM(C23:C29) -> 14 | D30: =SUM(D23:D29) -> 33250 | E30: =SUM(E23:E29) -> 20730

Sheet Meeting Actions
B1: Meeting Log & Action Items
B2: Decisions and actions from every meeting, with owners, due dates and an automatic overdue flag.
B4: Meeting date | C4: Meeting | D4: Platform | E4: Attendees | F4: Decision / key note | G4: Action item | H4: Owner | I4: Due | J4: Status | K4: Flag
B5: 46314 | C5: Leadership weekly | D5: MS Teams | E5: CEO, Ops, Finance, EA | F5: Q4 hiring freeze confirmed | G5: Circulate updated headcount plan | H5: Ops Manager | I5: 46318 | J5: Done | K5: =IF(J5="Done","Closed",IF(I5<AsOfDate,"Overdue",IF(I5-AsOfDate<=2,"Due soon","Open"))) -> Closed
B6: 46314 | C6: Leadership weekly | D6: MS Teams | E6: CEO, Ops, Finance, EA | F6: Board pack format agreed | G6: Draft board pack outline | H6: Ali | I6: 46321 | J6: Done | K6: =IF(J6="Done","Closed",IF(I6<AsOfDate,"Overdue",IF(I6-AsOfDate<=2,"Due soon","Open"))) -> Closed
B7: 46316 | C7: Client check-in: Northgate | D7: Zoom | E7: Account Mgr, Client CFO, EA | F7: Quarterly review set for 5 Nov | G7: Send quarterly review invite + agenda | H7: Ali | I7: 46317 | J7: Done | K7: =IF(J7="Done","Closed",IF(I7<AsOfDate,"Overdue",IF(I7-AsOfDate<=2,"Due soon","Open"))) -> Closed
B8: 46316 | C8: Client check-in: Northgate | D8: Zoom | E8: Account Mgr, Client CFO, EA | F8: Client to provide Q3 data | G8: Request Q3 data from client | H8: Account Manager | I8: 46323 | J8: In progress | K8: =IF(J8="Done","Closed",IF(I8<AsOfDate,"Overdue",IF(I8-AsOfDate<=2,"Due soon","Open"))) -> Overdue
B9: 46318 | C9: Finance review | D9: Google Meet | E9: Finance Lead, CEO, EA | F9: Escalate two 45+ day invoices | G9: Escalation emails: INV-1047, INV-1051 | H9: Finance Lead | I9: 46322 | J9: Open | K9: =IF(J9="Done","Closed",IF(I9<AsOfDate,"Overdue",IF(I9-AsOfDate<=2,"Due soon","Open"))) -> Overdue
B10: 46318 | C10: Finance review | D10: Google Meet | E10: Finance Lead, CEO, EA | F10: Twice-weekly AR routine approved | G10: Update SOP-04 with new routine | H10: Ali | I10: 46325 | J10: In progress | K10: =IF(J10="Done","Closed",IF(I10<AsOfDate,"Overdue",IF(I10-AsOfDate<=2,"Due soon","Open"))) -> Due soon
B11: 46321 | C11: Leadership weekly | D11: MS Teams | E11: CEO, Ops, Finance, EA | F11: Planning day on 14 Nov | G11: Confirm venue and catering numbers | H11: Ali | I11: 46323 | J11: In progress | K11: =IF(J11="Done","Closed",IF(I11<AsOfDate,"Overdue",IF(I11-AsOfDate<=2,"Due soon","Open"))) -> Overdue
B12: 46321 | C12: Leadership weekly | D12: MS Teams | E12: CEO, Ops, Finance, EA | F12: New PM tool to be trialled | G12: Set up 14-day trial workspace | H12: Ops Manager | I12: 46332 | J12: Open | K12: =IF(J12="Done","Closed",IF(I12<AsOfDate,"Overdue",IF(I12-AsOfDate<=2,"Due soon","Open"))) -> Open
B13: 46322 | C13: Pipeline meeting | D13: Zoom | E13: Sales Lead, CEO, EA | F13: Westfield proposal needs revised scope | G13: Revise Westfield scope (v2) | H13: Sales Lead | I13: 46326 | J13: Open | K13: =IF(J13="Done","Closed",IF(I13<AsOfDate,"Overdue",IF(I13-AsOfDate<=2,"Due soon","Open"))) -> Due soon
B14: 46322 | C14: Pipeline meeting | D14: Zoom | E14: Sales Lead, CEO, EA | F14: Stale leads to be re-contacted | G14: Follow up 3 stale leads in CRM | H14: Ali | I14: 46329 | J14: Open | K14: =IF(J14="Done","Closed",IF(I14<AsOfDate,"Overdue",IF(I14-AsOfDate<=2,"Due soon","Open"))) -> Open
B15: 46323 | C15: Training debrief: Session 3 | D15: Zoom | E15: Program Lead, EA | F15: 2 attendees below camera threshold | G15: Email both with rebooking options | H15: Ali | I15: 46325 | J15: Done | K15: =IF(J15="Done","Closed",IF(I15<AsOfDate,"Overdue",IF(I15-AsOfDate<=2,"Due soon","Open"))) -> Closed
B16: 46323 | C16: Training debrief: Session 3 | D16: Zoom | E16: Program Lead, EA | F16: Certificates to issue this week | G16: Issue CPD certificates | H16: Ali | I16: 46329 | J16: In progress | K16: =IF(J16="Done","Closed",IF(I16<AsOfDate,"Overdue",IF(I16-AsOfDate<=2,"Due soon","Open"))) -> Open
... B18: 46324 | C18: Onboarding stand-up | D18: In person | E18: Account Mgrs, EA | F18: Standard folder template agreed | G18: Publish folder template to shared drive | H18: Ali | I18: 46331 | J18: Open | K18: =IF(J18="Done","Closed",IF(I18<AsOfDate,"Overdue",IF(I18-AsOfDate<=2,"Due soon","Open"))) -> Open

Sheet Event & CPD Tracker
B1: Event & CPD Attendance Tracker
B2: Registration, reminders, attendance and camera compliance for a CPD webinar, with automatic eligibility. Mirrors SOP-05.
B4: Session | D4: Compliance Essentials: Session 3 (sample) | F4: Registered | H4: =COUNTA($B$12:$B$27) -> 16
B5: Date | D5: 46323 | F5: Attended | H5: =COUNTIF($I$12:$I$27,"Y") -> 14
B6: Duration (minutes) | D6: 90 | F6: Attendance rate | H6: =IFERROR(H5/H4,0) -> 0.875
B7: Minimum attendance for CPD | D7: 0.8 | F7: CPD eligible | H7: =COUNTIF($M$12:$M$27,"Eligible") -> 11
B8: Camera-on requirement | D8: 0.9 | F8: Certificates still to send | H8: =COUNTIFS($M$12:$M$27,"Eligible",$N$12:$N$27,"<>Y") -> 5
B11: Reg # | C11: Attendee | D11: Firm | E11: Email | F11: Registered | G11: Confirmation sent | H11: Reminders sent | I11: Attended | J11: Minutes attended | K11: Attendance % | L11: Camera-on % | M11: CPD eligible | N11: Certificate sent | O11: Next action
B12: R-301 | C12: J. Santos | D12: Harbourline Accounting | E12: jsantos@harbourlineacc.example.com | F12: 46302 | G12: Y | H12: Y | I12: Y | J12: 90 | K12: =IF(I12="Y",MIN(1,J12/$D$6),0) -> 1 | L12: 1 | M12: =IF(AND(I12="Y",K12>=$D$7,L12>=$D$8),"Eligible","Not eligible") -> Eligible | N12: Y | O12: =IF(M12="Eligible",IF(N12="Y","Complete","Send certificate"),IF(I12="Y","Explain requirement + rebook","Send recording + rebook")) -> Complete
B13: R-302 | C13: R. Patel | D13: Northgate Advisory | E13: rpatel@northgateadvis.example.com | F13: 46303 | G13: Y | H13: Y | I13: Y | J13: 88 | K13: =IF(I13="Y",MIN(1,J13/$D$6),0) -> 0.97777778 | L13: 0.95 | M13: =IF(AND(I13="Y",K13>=$D$7,L13>=$D$8),"Eligible","Not eligible") -> Eligible | N13: Y | O13: =IF(M13="Eligible",IF(N13="Y","Complete","Send certificate"),IF(I13="Y","Explain requirement + rebook","Send recording + rebook")) -> Complete
B14: R-303 | C14: M. Chen | D14: Cedar & Co. | E14: mchen@cedarco.example.com | F14: 46304 | G14: Y | H14: Y | I14: Y | J14: 90 | K14: =IF(I14="Y",MIN(1,J14/$D$6),0) -> 1 | L14: 1 | M14: =IF(AND(I14="Y",K14>=$D$7,L14>=$D$8),"Eligible","Not eligible") -> Eligible | N14: Y | O14: =IF(M14="Eligible",IF(N14="Y","Complete","Send certificate"),IF(I14="Y","Explain requirement + rebook","Send recording + rebook")) -> Complete
B15: R-304 | C15: A. Rivera | D15: Bluefin Consulting | E15: arivera@bluefinconsult.example.com | F15: 46305 | G15: Y | H15: Y | I15: Y | J15: 61 | K15: =IF(I15="Y",MIN(1,J15/$D$6),0) -> 0.67777778 | L15: 1 | M15: =IF(AND(I15="Y",K15>=$D$7,L15>=$D$8),"Eligible","Not eligible") -> Not eligible | N15: N | O15: =IF(M15="Eligible",IF(N15="Y","Complete","Send certificate"),IF(I15="Y","Explain requirement + rebook","Send recording + rebook")) -> Explain requirement + rebook
